tests/hard-long1.in
40
0-39 o
.
0 S 1 NVDA 121512 6809
7 B 2 GOOG 39514 632
5 S 3 FB 190410 7328
29 B 4 FB 165559 1447
18 S 5 TSLA 14483 69
23 S 6 TSLA 103926 3795
32 B 7 NVDA 152833 2270
15 S 8 NVDA 52395 1457
27 S 9 AAPL 17086 1371
5 B 10 FB 193105 3617
6 S 11 FB 14358 1725
10 S 12 AAPL 169639 7689
25 S 13 AMD 159334 7340
5 B 14 GOOG 167623 2579
1 S 15 NVDA 111707 8964
31 B 16 NVDA 174188 8212
21 S 17 NFLX 114452 6516
37 S 18 MSFT 21561 4410
38 B 19 TSLA 127350 591
11 S 20 AMZN 21225 8783
20 S 21 GOOG 62691 6327
38 S 22 AAPL 63062 8458
31 B 23 NVDA 12633 9742
20 S 24 NFLX 134268 9595
0 S 25 NVDA 47361 1870
29 S 26 INTC 55843 9260
6 S 27 NVDA 63731 1164
12 B 28 AMZN 121177 2852
20 S 29 NFLX 149033 9015
3 S 30 AMD 112305 8934
4 B 31 AAPL 113344 1134
10 S 32 MSFT 26018 2749
14 B 33 AMZN 87342 1118
34 S 34 AMZN 193801 7779
23 B 35 MSFT 107273 2404
15 S 36 TSLA 90824 595
36 B 37 GOOG 34964 4101
38 B 38 FB 42710 2885
19 S 39 NFLX 83598 8793
27 B 40 INTC 154006 5810
3 B 41 TSLA 72947 8539
2 S 42 AMD 43076 2614
36 B 43 INTC 88948 7030
39 B 44 AMD 195697 4469
7 B 45 GOOG 94391 1668
8 S 46 NVDA 101948 9028
28 B 47 FB 68129 2458
30 B 48 FB 68607 4161
12 B 49 AMZN 60061 7844
13 S 50 AMD 29521 6988
34 B 51 NVDA 68809 7815
34 B 52 NVDA 151770 1316
13 B 53 AAPL 117292 6572
21 B 54 AMZN 198435 1716
10 B 55 AMZN 70749 7447
32 B 56 AAPL 101296 1896
24 B 57 NVDA 62236 8029
33 B 58 AMZN 176865 1043
26 S 59 AMD 53388 2989
34 S 60 AAPL 7635 7345
7 S 61 FB 43886 7497
25 B 62 MSFT 101926 6172
27 B 63 FB 168788 2118
21 B 64 NVDA 78254 5164
12 B 65 AMD 76407 5501
28 B 66 MSFT 135288 8255
9 B 67 NVDA 73689 9005
38 B 68 MSFT 44041 7603
28 B 69 AAPL 146252 8232
3 B 70 GOOG 149394 2596
0 S 71 NFLX 188355 2044
37 B 72 AMZN 61404 4859
1 S 73 FB 186995 2552
21 B 74 MSFT 198425 3975
13 S 75 INTC 107226 408
21 S 76 INTC 142957 2300
11 B 77 AMZN 4646 1123
27 S 78 NFLX 158245 3996
18 S 79 AMD 115690 3361
25 B 80 NFLX 198020 4326
20 S 81 FB 164141 9401
1 S 82 GOOG 167926 4826
17 S 83 GOOG 149589 113
27 B 84 TSLA 6775 6346
12 B 85 AAPL 48813 5118
19 B 86 TSLA 180923 1700
2 B 87 AMD 156680 4356
31 B 88 INTC 864 5607
25 B 89 AMD 47437 5145
37 B 90 AMZN 75211 5078
17 B 91 TSLA 170352 3060
15 B 92 INTC 148278 3784
23 B 93 GOOG 38430 5900
14 B 94 TSLA 172171 1411
34 S 95 INTC 72770 8852
16 S 96 MSFT 91932 9614
19 S 97 AMZN 154842 4136
14 S 98 NFLX 43539 6312
37 S 99 TSLA 174982 1386
27 B 100 AAPL 68310 4023
33 B 101 TSLA 16469 7904
16 B 102 MSFT 76328 848
26 B 103 TSLA 24047 9244
31 S 104 NFLX 91597 9885
30 S 105 NVDA 99636 8289
21 B 106 MSFT 84266 2223
25 S 107 FB 31459 1183
9 S 108 AMD 191472 232
15 B 109 AMZN 25003 4572
13 S 110 FB 156580 1439
17 S 111 GOOG 152736 6794
21 S 112 AAPL 32865 2409
38 B 113 AMZN 50794 1926
2 S 114 AMD 165843 9550
34 B 115 NVDA 40552 2495
15 B 116 AAPL 73909 8564
14 B 117 AAPL 155723 8510
26 B 118 AAPL 193087 3626
21 S 119 AAPL 89148 6511
18 S 120 AMZN 106638 5168
10 S 121 GOOG 90431 6387
37 B 122 NFLX 21617 8888
12 B 123 TSLA 97989 4389
30 S 124 AAPL 86904 5072
29 S 125 FB 32812 606
21 B 126 GOOG 30692 5381
28 B 127 FB 199504 6915
18 B 128 NFLX 196096 9895
15 S 129 AMZN 191292 5191
0 S 130 FB 66892 1050
25 S 131 NFLX 141399 87
22 B 132 AMZN 151091 844
20 S 133 TSLA 57235 1079
7 S 134 MSFT 142927 3787
26 S 135 AMZN 42898 5522
38 B 136 INTC 52628 4387
23 S 137 AAPL 43996 2658
34 S 138 AAPL 109895 2848
28 B 139 AMD 48130 3404
13 B 140 AMD 3506 5907
24 S 141 TSLA 74639 5139
9 B 142 GOOG 37888 8741
26 B 143 TSLA 8122 4553
38 S 144 FB 43608 6467
26 B 145 MSFT 178651 2787
13 S 146 NFLX 192687 3171
31 B 147 TSLA 89442 2874
9 S 148 AMZN 138372 1080
33 S 149 INTC 81670 6437
14 S 150 TSLA 118218 9586
37 B 151 NFLX 109981 9535
6 B 152 FB 72572 8917
17 B 153 GOOG 139279 9962
13 B 154 NFLX 163615 8386
26 B 155 AMD 461 820
2 B 156 TSLA 19007 754
6 S 157 NVDA 162370 8780
18 S 158 AAPL 18004 2593
16 B 159 GOOG 185926 2220
2 B 160 AMD 52053 2915
14 B 161 NVDA 150310 9329
8 B 162 TSLA 187090 2265
30 B 163 AMZN 184459 697
4 B 164 AAPL 143801 2194
27 B 165 AMZN 108042 8610
36 B 166 AAPL 133619 2553
32 B 167 AMZN 194355 6679
32 S 168 AMZN 98927 42
34 B 169 TSLA 4323 9958
23 B 170 GOOG 47505 8572
16 S 171 FB 101895 724
23 S 172 FB 121093 1891
38 B 173 AMZN 153477 2718
5 B 174 NFLX 124829 405
14 S 175 GOOG 80973 3746
16 B 176 INTC 2363 2312
19 S 177 AMD 149471 7975
29 B 178 FB 5967 8879
27 S 179 FB 70068 6494
14 B 180 INTC 93752 593
34 S 181 FB 128009 4347
34 B 182 FB 137525 2925
4 B 183 AMZN 150003 8563
6 B 184 AMD 97074 2227
18 B 185 MSFT 535 6086
28 S 186 MSFT 26835 8425
0 B 187 AMZN 18235 2292
37 B 188 INTC 145213 2999
1 B 189 FB 179049 9075
9 B 190 FB 187378 5321
1 S 191 INTC 191068 4060
21 B 192 NVDA 171646 204
14 S 193 GOOG 89178 446
3 B 194 TSLA 105580 7609
16 S 195 GOOG 80930 797
24 S 196 GOOG 160806 9296
9 S 197 TSLA 30963 204
9 S 198 AAPL 68704 5013
16 B 199 NFLX 5266 3260
0 S 200 MSFT 121972 3780
37 S 201 GOOG 148736 1438
7 B 202 NFLX 76012 5181
36 S 203 AMD 111483 3546
4 B 204 AMD 112084 8076
26 B 205 AAPL 179293 532
24 S 206 NVDA 73721 1300
19 S 207 AMD 100233 4527
10 S 208 MSFT 25137 1633
16 B 209 TSLA 74149 333
5 B 210 MSFT 76538 7872
31 B 211 INTC 26835 7252
37 S 212 NFLX 29613 6418
20 S 213 NFLX 143532 3438
17 S 214 AMD 114734 2617
5 B 215 FB 116163 4051
27 S 216 AMD 56465 6520
36 B 217 GOOG 24129 5411
12 S 218 NFLX 111094 1419
7 B 219 INTC 82529 8200
20 B 220 AMZN 110904 9243
6 S 221 GOOG 5714 9290
37 B 222 AMZN 24322 7478
2 S 223 AMZN 32020 8483
15 S 224 AMD 31024 4251
24 B 225 TSLA 138413 8837
8 S 226 AMZN 147339 2915
6 B 227 INTC 148086 6194
24 B 228 MSFT 14953 8153
12 S 229 FB 74852 8405
33 S 230 GOOG 165947 1246
11 S 231 NVDA 117475 3715
7 B 232 NVDA 77852 5536
25 B 233 TSLA 115057 9698
9 B 234 NFLX 77297 2020
37 S 235 AMD 84004 1295
17 S 236 AMZN 64528 6107
38 B 237 NVDA 147270 9559
14 B 238 FB 86634 4558
8 S 239 MSFT 60182 8909
13 S 240 AMD 131846 8554
35 B 241 AAPL 144800 7078
34 S 242 INTC 169113 6778
22 B 243 INTC 53974 3684
25 B 244 MSFT 75781 7403
4 S 245 NVDA 159286 3446
39 B 246 GOOG 80978 1426
11 B 247 TSLA 5762 4147
10 B 248 FB 43465 8334
20 B 249 FB 137724 7392
36 S 250 AMD 24061 1712
27 S 251 MSFT 75265 9394
36 B 252 AMZN 184994 9701
30 B 253 INTC 67557 6991
37 S 254 AAPL 185957 4408
2 S 255 AMZN 81524 9744
26 S 256 FB 180148 6136
9 S 257 MSFT 92571 4543
17 B 258 TSLA 44041 358
6 S 259 TSLA 126016 4015
19 S 260 GOOG 101716 9672
4 S 261 FB 35207 3446
35 B 262 GOOG 44121 9952
26 S 263 NVDA 123683 6577
39 B 264 NVDA 86830 9745
21 S 265 FB 146298 1943
5 S 266 AAPL 164448 848
14 S 267 INTC 139250 1352
24 B 268 MSFT 23096 7843
31 S 269 NVDA 91086 1354
15 S 270 AAPL 114443 1907
11 S 271 AAPL 60059 8939
10 S 272 MSFT 2209 3001
35 B 273 INTC 8993 5982
11 B 274 NVDA 6408 9082
30 S 275 AMD 188159 4426
28 S 276 NFLX 91535 4704
14 B 277 MSFT 43232 789
38 S 278 AAPL 81414 6548
17 B 279 FB 94621 5367
17 B 280 FB 134255 516
29 S 281 INTC 179147 7544
32 S 282 NVDA 8278 9794
7 S 283 MSFT 66003 2343
16 B 284 AMD 168749 7935
39 S 285 TSLA 112662 5542
22 S 286 MSFT 67546 7888
3 B 287 GOOG 144134 5311
6 B 288 AMZN 183453 3538
9 S 289 AMD 20219 6313
24 S 290 NFLX 90212 5932
15 S 291 NFLX 106530 3629
32 S 292 GOOG 103109 8193
35 S 293 FB 33024 5003
37 B 294 AMZN 198310 8470
12 S 295 AMD 179728 6138
11 S 296 AAPL 24416 3396
31 S 297 TSLA 79958 3056
13 S 298 AMZN 7486 387
5 B 299 AMZN 151279 357
26 S 300 NFLX 112358 8865
25 B 301 AAPL 163353 9101
23 S 302 AMZN 32206 9192
39 S 303 AAPL 198264 1147
0 S 304 INTC 45742 917
16 S 305 AAPL 160712 6803
19 B 306 AMD 6912 6384
11 S 307 NFLX 63630 127
28 S 308 AMZN 100310 5277
6 B 309 NFLX 192131 8979
9 S 310 AMD 129642 1683
13 S 311 NFLX 68028 1029
9 S 312 INTC 191158 3618
4 B 313 AAPL 183659 7980
2 S 314 AAPL 91407 1190
3 S 315 INTC 46126 6036
28 B 316 INTC 191037 2798
37 S 317 AAPL 48103 6497
2 B 318 INTC 79840 3054
33 S 319 AAPL 180712 3397
17 B 320 GOOG 113116 8244
28 B 321 AMZN 156587 3955
22 B 322 INTC 88519 959
7 S 323 AMD 85533 1252
0 B 324 INTC 11686 2595
36 S 325 TSLA 148966 5295
22 S 326 INTC 88352 1
29 S 327 AMZN 163006 5448
19 B 328 AMD 45407 3951
