tests/hard-long2-reject-cancel.in
20
0-19 o
.
4 S 1 INTC 19743 3219
17 B 2 AAPL 56892 7091
1 B 3 NVDA 111360 3150
14 S 4 TSLA 46471 5319
14 S 5 TSLA 145625 4802
18 B 6 AAPL 79718 2812
16 S 7 GOOG 9606 5871
18 S 8 MSFT 1651 1416
4 B 9 AMZN 39322 1699
1 B 10 AMZN 170583 5326
0 B 11 AAPL 112905 1924
10 B 12 NFLX 148233 7669
4 S 13 INTC 10349 4080
2 S 14 TSLA 191087 9405
5 S 15 AAPL 5936 7879
13 S 16 INTC 38860 5867
7 S 17 NFLX 179873 8811
11 B 18 AMD 173997 1129
15 S 19 AMZN 185571 7048
15 B 20 AMD 89978 3552
12 S 21 MSFT 128334 8074
18 S 22 INTC 152972 5859
1 S 23 FB 52427 2187
7 S 24 GOOG 163772 5567
8 S 25 FB 50602 936
8 S 26 NFLX 145096 8172
8 S 27 FB 125775 8145
1 B 28 GOOG 153781 5985
9 S 29 NFLX 148272 4572
14 B 30 AMD 54920 8820
14 S 31 TSLA 21154 4816
6 S 32 TSLA 46914 905
11 B 33 NVDA 156775 2092
16 B 34 AMZN 94474 9962
10 B 35 MSFT 196963 1115
5 S 36 NVDA 19137 1711
4 S 37 TSLA 23153 2452
17 B 38 NFLX 37595 5925
8 B 39 FB 97584 858
17 B 40 AMD 63580 8387
9 S 41 TSLA 164793 5510
8 S 42 FB 184954 9161
2 S 43 INTC 16783 3419
8 S 44 AMZN 41386 2253
10 S 45 AMD 182125 5660
2 S 46 FB 26441 6519
13 B 47 GOOG 42793 4176
11 S 48 AMZN 141274 6473
2 S 49 GOOG 113819 1217
6 S 50 AAPL 175669 8401
15 S 51 TSLA 102578 6223
10 S 52 GOOG 158518 6186
12 B 53 NFLX 197336 8547
2 B 54 AAPL 69641 66
7 B 55 INTC 182931 1416
9 S 56 NVDA 114140 2040
16 S 57 INTC 83943 5137
11 B 58 MSFT 139447 3496
13 S 59 NVDA 142167 3397
13 B 60 AMZN 124619 5930
15 S 61 AMZN 108075 4417
10 B 62 INTC 114954 7486
17 S 63 MSFT 102934 9174
1 B 64 MSFT 36106 6612
8 B 65 MSFT 116136 3954
6 S 66 TSLA 93404 2862
18 B 67 NFLX 42455 8642
13 B 68 FB 108278 3759
6 S 69 TSLA 20985 5465
2 B 70 AAPL 189074 6905
4 S 71 NFLX 135211 8861
2 B 72 FB 27750 2903
17 S 73 TSLA 40921 5736
5 S 74 MSFT 25540 6401
6 B 75 AAPL 128160 4319
17 S 76 AAPL 133431 1228
5 S 77 AMZN 16252 9006
0 S 78 INTC 124517 9565
19 S 79 GOOG 196079 6909
11 S 80 NVDA 45298 8045
19 S 81 INTC 144261 9451
5 B 82 INTC 93508 6698
16 B 83 MSFT 185369 2848
16 S 84 NFLX 116636 2009
4 S 85 AMD 120430 6999
16 S 86 FB 122605 360
11 S 87 AMD 102250 9937
1 S 88 TSLA 156726 6464
2 B 89 INTC 103075 1251
19 B 90 AMZN 107043 9952
7 S 91 INTC 57493 7052
15 S 92 AAPL 104058 9159
13 B 93 NVDA 109951 8168
0 B 94 AAPL 179206 3208
11 S 95 NFLX 124279 9290
8 B 96 FB 148334 737
5 S 97 NFLX 135684 661
7 B 98 AMZN 130787 8785
8 S 99 GOOG 111573 3201
12 B 100 GOOG 58695 593
2 S 101 NFLX 53469 6632
9 S 102 FB 55354 7381
12 B 103 AMZN 76978 1646
0 B 104 TSLA 151461 8122
16 S 105 MSFT 124675 9392
17 S 106 AMD 160587 4493
14 S 107 NFLX 132055 2551
3 B 108 NVDA 4380 4280
13 S 109 AAPL 127753 5058
8 S 110 AAPL 29118 7644
7 B 111 AMD 150923 3649
10 B 112 FB 9087 3009
3 B 113 TSLA 190961 3832
12 B 114 GOOG 191356 1775
14 S 115 AMZN 19479 7990
5 S 116 NVDA 97608 7177
7 S 117 FB 182548 5975
5 S 118 NVDA 64765 9593
17 B 119 INTC 196646 6382
8 B 120 TSLA 8762 6833
18 S 121 AMD 33772 9816
9 S 122 NFLX 125182 2528
8 B 123 NFLX 158837 211
19 B 124 AAPL 146445 2878
14 B 125 AMD 162869 1826
18 B 126 AAPL 9111 7166
2 S 127 INTC 69699 7710
3 S 128 AMD 99013 6021
4 B 129 NVDA 127433 2512
14 B 130 GOOG 12797 4208
6 B 131 TSLA 85161 9358
15 S 132 MSFT 69065 2899
18 B 133 INTC 93237 9614
10 B 134 NVDA 145348 4942
17 B 135 NFLX 65018 6933
19 B 136 TSLA 183461 534
12 B 137 AAPL 17155 9762
9 S 138 GOOG 18044 4626
3 S 139 INTC 166756 2307
9 B 140 AAPL 30206 516
14 B 141 TSLA 161543 8446
3 B 142 AMZN 64514 6990
19 B 143 NFLX 3906 8056
19 B 144 AMZN 193016 3629
8 B 145 FB 187010 1766
19 S 146 TSLA 174456 3462
1 B 147 GOOG 67859 3463
13 B 148 AAPL 100938 8177
5 B 149 NFLX 6982 450
10 S 150 AMZN 159100 8645
19 B 151 FB 53145 7245
8 S 152 NFLX 3368 823
13 B 153 GOOG 114719 1182
15 B 154 GOOG 57722 7982
16 S 155 GOOG 3654 3154
16 S 156 GOOG 83138 2657
8 S 157 TSLA 61771 4437
5 B 158 INTC 147261 5520
12 S 159 GOOG 197460 650
9 S 160 TSLA 150772 1874
13 B 161 AMD 102882 9350
5 S 162 NVDA 18551 3095
19 B 163 INTC 64343 1098
14 B 164 FB 197248 2239
15 B 165 TSLA 100199 1264
6 B 166 GOOG 24727 1934
1 S 167 NVDA 196423 9794
8 B 168 INTC 38826 1502
3 S 169 AMZN 126693 7278
12 B 170 NVDA 76184 7998
17 B 171 AMD 140664 8723
5 S 172 AMZN 180949 5603
12 B 173 NFLX 58124 1639
7 S 174 GOOG 71469 5925
4 S 175 FB 125069 5732
18 B 176 GOOG 75536 1945
16 S 177 GOOG 15613 5672
14 B 178 INTC 11574 6839
2 S 179 INTC 97491 9671
1 S 180 TSLA 157430 1604
6 S 181 NFLX 145181 6160
18 B 182 NFLX 158338 9498
18 B 183 AMD 77632 8672
5 S 184 NVDA 173121 7975
3 B 185 TSLA 18227 3718
12 S 186 GOOG 173103 9105
3 B 187 FB 178383 1560
8 B 188 AMD 89027 8258
17 S 189 NVDA 100567 1155
10 B 190 NVDA 26160 6551
5 B 191 AMZN 9522 7734
16 B 192 FB 79117 1372
2 B 193 AAPL 30472 8629
18 S 194 GOOG 31965 2462
0 B 195 NFLX 125341 7868
16 S 196 NFLX 163953 4421
8 B 197 GOOG 7118 635
18 B 198 AMZN 178775 4684
6 S 199 MSFT 94828 7207
17 S 200 AMD 122676 5635
1 B 201 NVDA 9901 936
15 S 202 TSLA 162913 1001
1 S 203 MSFT 35320 2150
9 S 204 NFLX 83945 4688
14 B 205 AMZN 115184 4386
15 B 206 NVDA 8791 4230
18 S 207 AAPL 185758 9923
7 S 208 INTC 117507 9995
3 B 209 TSLA 140206 130
11 S 210 FB 23361 3829
14 S 211 INTC 77203 5898
7 S 212 NFLX 30403 4306
17 S 213 AMD 52510 4001
14 B 214 AAPL 33338 8840
3 S 215 INTC 199032 2032
9 S 216 TSLA 21767 3741
11 B 217 INTC 143245 5080
17 B 218 FB 193001 808
16 B 219 FB 190842 8339
2 B 220 AMZN 101397 8803
2 B 221 AMD 120291 8104
17 S 222 TSLA 175230 4462
0 B 223 TSLA 36981 7792
2 S 224 NVDA 193824 6046
16 S 225 TSLA 1901 3647
3 B 226 AAPL 101646 4347
2 B 227 FB 164887 2346
9 B 228 MSFT 58581 8931
0 B 229 MSFT 124993 3956
19 S 230 NFLX 135791 5504
0 B 231 AAPL 69941 4699
16 B 232 FB 28952 2321
15 S 233 INTC 132206 8144
12 S 234 AMD 162030 6407
18 S 235 NVDA 75945 3068
16 B 236 INTC 182915 8075
0 B 237 FB 133874 7130
9 B 238 AMZN 43148 640
11 B 239 AAPL 70751 793
1 B 240 INTC 94902 6202
16 S 241 AMD 26926 6068
1 S 242 FB 27229 659
16 S 243 MSFT 192406 1033
9 B 244 AAPL 49928 5288
12 S 245 AAPL 69483 7599
13 S 246 NFLX 8709 7724
19 S 247 INTC 13944 1587
7 B 248 NFLX 143043 8926
4 B 249 AMZN 98700 4418
1 B 250 AMD 139498 6252
4 B 251 FB 169171 883
14 B 252 FB 144901 2186
7 B 253 AMD 158406 686
6 B 254 FB 37117 4374
14 B 255 AMD 53849 2291
5 S 256 TSLA 170858 9440
10 S 257 NVDA 148413 9614
16 B 258 NFLX 66727 4674
0 B 259 TSLA 97709 9380
2 S 260 MSFT 154696 5930
9 S 261 AMD 166981 4542
9 S 262 NVDA 153216 7046
15 B 263 GOOG 153353 9788
16 B 264 AMD 186613 9204
14 B 265 FB 192304 4395
7 B 266 NVDA 101584 4233
5 B 267 AMD 150397 2668
19 B 268 INTC 155254 1766
10 B 269 AAPL 95290 2785
4 B 270 FB 112914 6796
1 B 271 AMZN 137207 7344
1 B 272 NFLX 108833 457
12 B 273 AMD 11274 3246
7 S 274 GOOG 60357 9673
11 B 275 GOOG 193091 723
19 S 276 MSFT 62254 6391
17 B 277 NVDA 169092 3479
17 S 278 FB 16856 2018
10 S 279 NFLX 197862 1042
13 S 280 AMZN 55561 19
8 B 281 TSLA 147883 2331
4 B 282 AMD 59888 4759
9 B 283 MSFT 5147 3506
5 S 284 INTC 52883 774
19 S 285 AMD 86765 2022
17 B 286 NVDA 93740 8920
15 S 287 AMD 148427 8065
2 B 288 TSLA 241 499
7 B 289 NFLX 94884 3055
2 S 290 TSLA 21791 1143
10 S 291 AAPL 123765 5604
19 B 292 NFLX 193736 8226
0 S 293 INTC 21929 5840
2 B 294 NFLX 8962 8197
6 B 295 NFLX 150038 7032
0 S 296 AMZN 105146 2688
2 B 297 INTC 142506 9015
17 B 298 AMZN 182436 8913
1 S 299 AMZN 131110 6614
11 B 300 AAPL 192718 4217
19 S 301 NVDA 116822 1259
14 B 302 AMD 169099 6639
10 S 303 GOOG 67878 567
10 S 304 MSFT 195345 505
3 B 305 AMD 128560 6438
7 S 306 AMZN 116239 9901
0 B 307 NFLX 110158 9074
10 S 308 NFLX 135410 4440
4 S 309 TSLA 190520 7410
4 B 310 AAPL 149665 9996
8 S 311 AAPL 59015 7590
12 S 312 AMD 167618 477
12 S 313 NVDA 111861 9836
4 B 314 NVDA 109178 8198
16 S 315 NFLX 108394 2012
2 B 316 INTC 152457 4966
8 B 317 AAPL 108844 1094
3 B 318 NVDA 12832 4688
16 S 319 MSFT 122859 8535
15 S 320 NVDA 137255 5896
6 B 321 AMZN 19404 3714
4 B 322 AAPL 194497 2843
6 S 323 NFLX 6501 8304
16 B 324 AMZN 1904 6048
19 S 325 NVDA 3040 8544
14 B 326 AAPL 19394 759
11 B 327 GOOG 152314 8089
12 B 328 AMZN 122020 9743
6 S 329 INTC 63448 4940
2 S 330 AAPL 59853 1045
